<robot name="my_robot">
  <material name="blue">
    <color rgba="0 0 1 1"/>
  </material>
  <material name="green">
    <color rgba="0 1 0 1"/>
  </material>

  <material name="black">
    <color rgba="0 0 0 1"/>
  </material>

  <material name="white">
    <color rgba="1 1 1 1"/>
  </material>

  <!-- Base link -->
  <link name="base_link">
    <visual>
      <geometry>
        <box size="0.3 0.2 0.15"/>
      </geometry>
      <material name="blue"/>
    </visual>
    <collision>
      <geometry>
        <box size="0.3 0.2 0.15"/>
      </geometry>
    </collision>
    <inertial>
        <mass value="5.0"/>
        <inertia ixx="0.0260417" ixy="0" ixz="0" iyy="0.046875" iyz="0" izz="0.0541667"/>
    </inertial>
  </link>

  <!-- Left wheel link -->
  <link name="left_wheel_link">
    <visual>
      <geometry>
        <cylinder length="0.05" radius="0.05"/>
      </geometry>
      <material name="green"/>
      <origin xyz="0 0 0" rpy = "0 0 0" />
    </visual>
    <collision>
      <geometry>
        <cylinder length="0.05" radius="0.05"/>
      </geometry>
      <origin xyz="0 0 0" rpy = "0 0 0" />
    </collision>
    <inertial>
      <mass value="0.5"/>
      <inertia ixx="0.0004167" ixy="0" ixz="0" iyy="0.0004167" iyz="0" izz="0.000625"/>
      <origin xyz="0 0 0" rpy = "0 0 0" />
    </inertial>
  </link>

  <!-- Right wheel link -->
  <link name="right_wheel_link">
    <visual>
      <geometry>
        <cylinder length="0.05" radius="0.05"/>
      </geometry>
      <material name="green"/>
      <origin xyz="0 0 0" rpy = "0 0 0" />
    </visual>
    <collision>
      <geometry>
        <cylinder length="0.05" radius="0.05"/>
      </geometry>
      <origin xyz="0 0 0" rpy = "0 0 0" />
    </collision>
    <inertial>
        <mass value="0.5"/>
        <inertia ixx="0.0004167" ixy="0" ixz="0" iyy="0.0004167" iyz="0" izz="0.000625"/>
        <origin xyz="0 0 0" rpy = "0 0 0" />
    </inertial>
  </link>

  <!-- Caster Wheel -->
  <link name="caster_wheel">
    <visual>
      <geometry>
        <sphere radius="0.025"/>
      </geometry>

      <material name="black"/>
    </visual>

    <collision>
      <geometry>
        <sphere radius= "0.025"/>
      </geometry>
    </collision>

    <inertial>
      <mass value="0.1"/>
      <inertia ixx="0.00025" ixy="0" ixz="0" iyy="0.00025" iyz="0" izz="0.00025"/>
    </inertial>
  </link>

  <!-- Caster Wheel joint -->
  <joint name ="caster_wheel_joint" type="fixed">
    <parent link= "base_link" />
    <child link = "caster_wheel" />
    <origin xyz="-0.125 0 -0.085" />
    <axis xyz="0 0 1" />
  </joint>

  <!-- Left wheel joint -->
  <joint name="left_wheel_joint" type="continuous">
    <parent link="base_link"/>
    <child link="left_wheel_link"/>
    <origin rpy="1.5708 0 0" xyz="0.06 -0.125 -0.06"/>
    <axis xyz="0 0 1"/>
  </joint>

  <!-- Right wheel joint -->
  <joint name="right_wheel_joint" type="continuous">
    <parent link="base_link"/>
    <child link="right_wheel_link"/>
    <origin rpy="1.5708 0 0" xyz="0.06 0.125 -0.06"/>
    <axis xyz="0 0 1"/>
  </joint>


  <!-- LiDAR link -->
  <link name="laser_link">
      <visual>
          <geometry>
              <cylinder length="0.025" radius="0.05"/>
          </geometry>
          <material name="green"/>
      </visual>
      <collision>
          <geometry>
              <cylinder length="0.025" radius="0.05"/>
          </geometry>
      </collision>
      <inertial>
          <mass value="0.2"/>
          <inertia ixx="0.001" ixy="0" ixz="0" iyy="0.001" iyz="0" izz="0.001"/>
      </inertial>
  </link>

  <joint name="laser_joint" type="fixed">
    <parent link="base_link"/>
    <child link="laser_link"/>
    <origin rpy="0 0 0" xyz="0 0 0.085"/>
  </joint>

  <!-- IMU link -->
  <link name="imu_link"/>
  <joint name="imu_joint" type="fixed">
    <parent link="base_link"/>
    <child link="imu_link"/>
    <origin rpy="0 0 0" xyz="0 0 0.05"/>
  </joint>

  <gazebo reference="base_link">
      <material>Gazebo/Blue</material>
  </gazebo>

  <gazebo reference="caster_wheel">
      <material>Gazebo/Black</material>
      <mu1 value="0"/>
      <mu2 value="0"/>
  </gazebo>

  <gazebo reference="left_wheel">
      <material>Gazebo/Black</material>
      <mu1 value="1.0"/>
      <mu2 value="1.0"/>
  </gazebo>

  <gazebo reference="right_wheel">
      <material>Gazebo/Black</material>
      <mu1 value="1.0"/>
      <mu2 value="1.0"/>
  </gazebo>

  <gazebo>

    <plugin name="differential_drive_controller" filename="libgazebo_ros_diff_drive.so">
      <update_rate>50</update_rate>

      <left_joint>left_wheel_joint</left_joint>
      <right_joint>right_wheel_joint</right_joint>

      <wheel_separation>0.35</wheel_separation>
      <wheel_diameter>0.2</wheel_diameter>
	    <max_wheel_torque>20</max_wheel_torque>
	    <max_wheel_acceleration>1.0</max_wheel_acceleration>

	    <command_topic>cmd_vel</command_topic>
	    <publish_odom>true</publish_odom>
	    <publish_odom_tf>true</publish_odom_tf>
	    <publish_wheel_tf>true</publish_wheel_tf>
      <odometry_topic>odom</odometry_topic>

	    <odometry_frame>odom</odometry_frame>
	    <robot_base_frame>base_link</robot_base_frame>

	  </plugin>
	
    <plugin name="joint_state_publisher" filename="libgazebo_ros_joint_state_publisher.so">

      <update_rate>50</update_rate>

      <joint_name>left_wheel_joint</joint_name>
      <joint_name>right_wheel_joint</joint_name>

    </plugin>
  </gazebo>

  <!-- Gazebo sensor plugin for LiDAR -->
  <gazebo reference="laser_link">
    <sensor name="laser" type="ray">
      <pose>0 0 0 0 0 0</pose>
      <always_on>true</always_on>
      <visualize>true</visualize>
      <update_rate>30</update_rate>
      <ray>
        <scan>
          <horizontal>
            <samples>360</samples>
            <resolution>1</resolution>
            <min_angle>-3.14159</min_angle>
            <max_angle>3.14159</max_angle>
          </horizontal>
        </scan>
        <range>
          <min>0.12</min>
          <max>3.5</max>
          <resolution>0.01</resolution>
        </range>
      </ray>
      <plugin filename="libgazebo_ros_ray_sensor.so" name="scan">
        <topicName>/scan</topicName>
        <frameName>laser_link</frameName>
        <updateRate>30</updateRate>
        <output_type>sensor_msgs/LaserScan</output_type>
      </plugin>
    </sensor>
  </gazebo>

  <!-- Gazebo sensor plugin for IMU -->

 <gazebo reference="imu_link">
    <gravity>true</gravity>
    <sensor name="imu" type="imu">
      <always_on>true</always_on>
      <update_rate>100</update_rate>
      <visualize>true</visualize>
      <topic>/imu</topic>
      <plugin filename="libgazebo_ros_imu_sensor.so" name="imu_plugin">
        <topicName>/imu</topicName>
        <bodyName>imu_link</bodyName>
        <updateRateHZ>10.0</updateRateHZ>
        <gaussianNoise>0.0</gaussianNoise>
        <xyzOffset>0 0 0</xyzOffset>
        <rpyOffset>0 0 0</rpyOffset>
        <frameName>imu_link</frameName>
        <initialOrientationAsReference>true</initialOrientationAsReference>
      </plugin>
      <pose>0 0 0 0 0 0</pose>
    </sensor>
  </gazebo>

  <model>
    <name>turtlebot3_autorace_2020</name>
    <version>1.0</version>
    <sdf version='1.6'>model.sdf</sdf>
    <author>
      <name>ROBOTIS</name>
      <email>support@robotis.com</email>
    </author>
    <description>TurtleBot3 AutoRace 2020 Model</description>
  </model>


</robot>
